<?xml version="1.0" ?>
<!-- =================================================================================== -->
<!-- |    This document was autogenerated by xacro from /home/fayyu/test_ws/src/edrone_gazebo/urdf/edrone_model.urdf.xacro | -->
<!-- |    EDITING THIS FILE BY HAND IS NOT RECOMMENDED                                 | -->
<!-- =================================================================================== -->
<robot name="edrone_gazebo" xmlns:xacro="http://ros.org/wiki/xacro">

  <link name="base_link"/>
  <joint name="base_joint" type="fixed">
    <origin rpy="0 0 0" xyz="0 0 0"/>
    <parent link="base_link"/>
    <child link="base_link_inertia"/>
  </joint>
  <link name="base_link_inertia">
    <inertial>
      <mass value="0.0085"/>
      <!-- <mass value="0.1"/> -->
      <!-- [kg] -->
      <origin xyz="0 0 0"/>
      <!--| 7860832.000000 354.224915 9223.249023 |
          | 354.224915 15785238.000000 514.304504 |
          | 9223.249023 514.304504 8033247.000000 | -->  
      <!-- <inertia ixx="1212.180604086" ixy="0.054623298" ixz="1.422272295" iyy="2434.164644974" iyz="0.079308392" izz="1238.767881216"/> -->
      <inertia ixx="0.00001" ixy="0.0" ixz="0.0"
        iyy="0.00001" iyz="0.0" 
        izz="0.00001"/>
    </inertial>
    <visual>
      <origin rpy="1.57079632679 0 0" xyz="0 0 0" />
      <geometry>
        <mesh filename="package://edrone_gazebo/urdf/meshes/frame.dae" scale="0.001 0.001 0.001"/>
        <!-- <box size="${body_width} ${body_width} ${body_height}"/> -->
        <!-- [m] [m] [m] -->
      </geometry>
    </visual>
    <collision>
      <origin rpy="0 0 0" xyz="0 0 0"/>
      <geometry>
        <box size="0.14 0.14 0.015"/>
        <!-- [m] [m] [m] -->
      </geometry>
    </collision>
  </link>


  <!-- attach multirotor_base_plugin to the base_link -->
  <gazebo>
    <plugin filename="librotors_gazebo_multirotor_base_plugin.so" name="rosbag">
      <robotNamespace>edrone_gazebo</robotNamespace>
      <linkName>base_link</linkName>
      <rotorVelocitySlowdownSim>10</rotorVelocitySlowdownSim>
    </plugin>
  </gazebo>
  <gazebo reference="base_link">
    <material>Gazebo/DarkGrey</material>
  </gazebo>
  <!-- ===========================front left motor========================= -->
  <joint name="rotor_0_joint" type="continuous">
    <origin rpy="0 0 0" xyz="0.046 -0.046 0.0125"/>
    <axis xyz="0 0 1"/>
    <!-- TODO(ff): not currently set because it's not yet supported -->
    <!-- <limit effort="2000" velocity="${max_rot_velocity}" /> -->
    <parent link="base_link_inertia"/>
    <child link="rotor_0"/>
  </joint>
  <!-- TODO(ff): not currently set because it's not yet supported -->
  <!-- <gazebo reference="rotor_${motor_number}_joint"> <axis> <xyz>0 0 1</xyz>
      <limit> <velocity> ${max_rot_velocity} </velocity> </limit> </axis> </gazebo> -->

  <link name="rotor_0">
    <inertial>
      <mass value="0.0037"/>
      <!-- [kg] -->
      <inertia ixx="7.215e-07" ixy="0.0" ixz="0.0" iyy="1.78833333333e-07" iyz="0.0" izz="8.44833333333e-07"/>
    </inertial>
    <visual>
      <origin rpy="0 0 1.57079632679" xyz="0 0 0" />
      <geometry>
        <!-- <cylinder length="0.005" radius="${radius_rotor}"/> -->
        <!-- [m] -->
        <!-- <mesh filename="package://rotors_description/meshes/propeller_${direction}.dae" -->
        <mesh filename="package://edrone_gazebo/urdf/meshes/iris_prop_ccw.dae" scale="0.15 0.15 0.15"/>
        <!-- <box size="${2*radius_rotor} 0.01 0.005"/> -->
      </geometry>
    </visual>
    <collision>
      <geometry>
        <cylinder length="0.005" radius="0.0035"/>
        <!-- [m] -->
      </geometry>
    </collision>
  </link>
  <gazebo>
    <plugin filename="librotors_gazebo_motor_model.so" name="front_motor_model">
      <robotNamespace>edrone_gazebo</robotNamespace>
      <jointName>rotor_0_joint</jointName>
      <linkName>rotor_0</linkName>
      <turningDirection>CCW_45</turningDirection>
      <timeConstantUp>0.15</timeConstantUp>
      <timeConstantDown>0.15</timeConstantDown>
      <maxRotVelocity>770</maxRotVelocity>
      <motorConstant>2.39e-05</motorConstant>
      <momentConstant>0.016</momentConstant>
      <commandSubTopic>gazebo/command/motor_speed</commandSubTopic>
      <motorNumber>0</motorNumber>
      <rotorDragCoefficient>1.3858e-06</rotorDragCoefficient>
      <rollingMomentCoefficient>1e-06</rollingMomentCoefficient>
      <motorSpeedPubTopic>motor_speed/0</motorSpeedPubTopic>
      <rotorVelocitySlowdownSim>10</rotorVelocitySlowdownSim>
    </plugin>
  </gazebo>

  <gazebo reference="rotor_0">
    <material>Gazebo/Blue</material>
  </gazebo>

  <!-- ========================Front Right motor============================================ -->
  <joint name="rotor_1_joint" type="continuous">
    <origin rpy="0 0 0" xyz="-0.046 -0.046 0.0125"/>
    <axis xyz="0 0 1"/>
    <!-- TODO(ff): not currently set because it's not yet supported -->
    <!-- <limit effort="2000" velocity="${max_rot_velocity}" /> -->
    <parent link="base_link_inertia"/>
    <child link="rotor_1"/>
  </joint>
  <!-- TODO(ff): not currently set because it's not yet supported -->
  <!-- <gazebo reference="rotor_${motor_number}_joint"> <axis> <xyz>0 0 1</xyz>
      <limit> <velocity> ${max_rot_velocity} </velocity> </limit> </axis> </gazebo> -->

  <link name="rotor_1">
    <inertial>
      <mass value="0.0037"/>
      <!-- [kg] -->
      <inertia ixx="7.215e-07" ixy="0.0" ixz="0.0" iyy="1.78833333333e-07" iyz="0.0" izz="8.44833333333e-07"/>
    </inertial>
    <visual>
      <origin rpy="0 0 1.57079632679" xyz="0 0 0" />
      <geometry>
        <!-- <cylinder length="0.005" radius="${radius_rotor}"/> -->
        <!-- [m] -->
        <!-- <mesh filename="package://rotors_description/meshes/propeller_${direction}.dae" -->
        <mesh filename="package://edrone_gazebo/urdf/meshes/iris_prop_cw.dae" scale="0.15 0.15 0.15"/>
        <!-- <box size="${2*radius_rotor} 0.01 0.005"/> -->
      </geometry>
    </visual>
    <collision>
      <geometry>
        <cylinder length="0.005" radius="0.0035"/>
        <!-- [m] -->
      </geometry>
    </collision>
  </link>

  <gazebo>
    <plugin filename="librotors_gazebo_motor_model.so" name="right_motor_model">
      <robotNamespace>edrone_gazebo</robotNamespace>
      <jointName>rotor_1_joint</jointName>
      <linkName>rotor_1</linkName>
      <turningDirection>CW_45</turningDirection>
      <timeConstantUp>0.15</timeConstantUp>
      <timeConstantDown>0.15</timeConstantDown>
      <maxRotVelocity>770</maxRotVelocity>
      <motorConstant>2.39e-05</motorConstant>
      <momentConstant>0.016</momentConstant>
      <commandSubTopic>gazebo/command/motor_speed</commandSubTopic>
      <motorNumber>1</motorNumber>
      <rotorDragCoefficient>1.3858e-06</rotorDragCoefficient>
      <rollingMomentCoefficient>1e-06</rollingMomentCoefficient>
      <motorSpeedPubTopic>motor_speed/1</motorSpeedPubTopic>
      <rotorVelocitySlowdownSim>10</rotorVelocitySlowdownSim>
    </plugin>
  </gazebo>
  <gazebo reference="rotor_1">
    <material>Gazebo/Grey</material>
  </gazebo>

  <!-- =====================================back right motor================================== -->
  <joint name="rotor_2_joint" type="continuous">
    <origin rpy="0 0 0" xyz="-0.046 0.046 0.0125"/>
    <axis xyz="0 0 1"/>
    <!-- TODO(ff): not currently set because it's not yet supported -->
    <!-- <limit effort="2000" velocity="${max_rot_velocity}" /> -->
    <parent link="base_link_inertia"/>
    <child link="rotor_2"/>
  </joint>
  <!-- TODO(ff): not currently set because it's not yet supported -->
  <!-- <gazebo reference="rotor_${motor_number}_joint"> <axis> <xyz>0 0 1</xyz>
      <limit> <velocity> ${max_rot_velocity} </velocity> </limit> </axis> </gazebo> -->

  
  <link name="rotor_2">
    <inertial>
      <mass value="0.0037"/>
      <!-- [kg] -->
      <inertia ixx="7.215e-07" ixy="0.0" ixz="0.0" iyy="1.78833333333e-07" iyz="0.0" izz="8.44833333333e-07"/>
    </inertial>
    <visual>
      <origin rpy="0 0 1.57079632679" xyz="0 0 0" />
      <geometry>
        <!-- <cylinder length="0.005" radius="${radius_rotor}"/> -->
        <!-- [m] -->
        <!-- <mesh filename="package://rotors_description/meshes/propeller_${direction}.dae" -->
        <mesh filename="package://edrone_gazebo/urdf/meshes/iris_prop_ccw.dae" scale="0.15 0.15 0.15"/>
        <!-- <box size="${2*radius_rotor} 0.01 0.005"/> -->
      </geometry>
    </visual>
    <collision>
      <geometry>
        <cylinder length="0.005" radius="0.0035"/>
        <!-- [m] -->
      </geometry>
    </collision>
  </link>
  <gazebo>
    <plugin filename="librotors_gazebo_motor_model.so" name="back_motor_model">
      <robotNamespace>edrone_gazebo</robotNamespace>
      <jointName>rotor_2_joint</jointName>
      <linkName>rotor_2</linkName>
      <turningDirection>CCW_45</turningDirection>
      <timeConstantUp>0.15</timeConstantUp>
      <timeConstantDown>0.15</timeConstantDown>
      <maxRotVelocity>770</maxRotVelocity>
      <motorConstant>2.39e-05</motorConstant>
      <momentConstant>0.016</momentConstant>
      <commandSubTopic>gazebo/command/motor_speed</commandSubTopic>
      <motorNumber>2</motorNumber>
      <rotorDragCoefficient>1.3858e-06</rotorDragCoefficient>
      <rollingMomentCoefficient>1e-06</rollingMomentCoefficient>
      <motorSpeedPubTopic>motor_speed/2</motorSpeedPubTopic>
      <rotorVelocitySlowdownSim>10</rotorVelocitySlowdownSim>
    </plugin>
  </gazebo>
  <gazebo reference="rotor_2">
    <material>Gazebo/black</material>
  </gazebo>

  <!-- ========================back left motor============================= -->
  <joint name="rotor_3_joint" type="continuous">
    <origin rpy="0 0 0" xyz="0.046 0.046 0.0125"/>
    <axis xyz="0 0 1"/>
    <!-- TODO(ff): not currently set because it's not yet supported -->
    <!-- <limit effort="2000" velocity="${max_rot_velocity}" /> -->
    <parent link="base_link_inertia"/>
    <child link="rotor_3"/>
  </joint>
  <!-- TODO(ff): not currently set because it's not yet supported -->
  <!-- <gazebo reference="rotor_${motor_number}_joint"> <axis> <xyz>0 0 1</xyz>
      <limit> <velocity> ${max_rot_velocity} </velocity> </limit> </axis> </gazebo> -->

  <link name="rotor_3">
    <inertial>
      <mass value="0.0037"/>
      <!-- [kg] -->
      <inertia ixx="7.215e-07" ixy="0.0" ixz="0.0" iyy="1.78833333333e-07" iyz="0.0" izz="8.44833333333e-07"/>
    </inertial>
    <visual>
      <origin rpy="0 0 1.57079632679" xyz="0 0 0" />
      <geometry>
        <!-- <cylinder length="0.005" radius="${radius_rotor}"/> -->
        <!-- [m] -->
        <!-- <mesh filename="package://rotors_description/meshes/propeller_${direction}.dae" -->
        <mesh filename="package://edrone_gazebo/urdf/meshes/iris_prop_cw.dae" scale="0.15 0.15 0.15"/>
        <!-- <box size="${2*radius_rotor} 0.01 0.005"/> -->
      </geometry>
    </visual>
    <collision>
      <geometry>
        <cylinder length="0.005" radius="0.0035"/>
        <!-- [m] -->
      </geometry>
    </collision>
  </link>
  <gazebo>
    <plugin filename="librotors_gazebo_motor_model.so" name="left_motor_model">
      <robotNamespace>edrone_gazebo</robotNamespace>
      <jointName>rotor_3_joint</jointName>
      <linkName>rotor_3</linkName>
      <turningDirection>CW_45</turningDirection>
      <timeConstantUp>0.15</timeConstantUp>
      <timeConstantDown>0.15</timeConstantDown>
      <maxRotVelocity>770</maxRotVelocity>
      <motorConstant>2.39e-05</motorConstant>
      <momentConstant>0.016</momentConstant>
      <commandSubTopic>gazebo/command/motor_speed</commandSubTopic>
      <motorNumber>3</motorNumber>
      <rotorDragCoefficient>1.3858e-06</rotorDragCoefficient>
      <rollingMomentCoefficient>1e-06</rollingMomentCoefficient>
      <motorSpeedPubTopic>motor_speed/3</motorSpeedPubTopic>
      <rotorVelocitySlowdownSim>10</rotorVelocitySlowdownSim>
    </plugin>
  </gazebo>
  <gazebo reference="rotor_3">
    <material>Gazebo/Grey</material>
  </gazebo>

</robot>