<?xml version="1.0" ?>

<robot name="edrone_model" xmlns:xacro="http://www.ros.org/wiki/xacro">

  <!-- Defining the colors used in this robot -->
  <material name="Black">
    <color rgba="0.0 0.0 0.0 1.0"/>
  </material>
  <material name="Red">
    <color rgba="0.8 0.0 0.0 1.0"/>
  </material>
  <material name="Green">
    <color rgba="0.0 0.8 0.0 1.0"/>
  </material>
  <material name="White">
    <color rgba="1.0 1.0 1.0 1.0"/>
  </material>
  <material name="Blue">
    <color rgba="0.0 0.0 0.8 1.0"/>
  </material>
  --&gt;

  <!-- BASE-LINK -->
  <!--Actual body/chassis of the robot-->
  <link name="frame_link">
    <visual>
      <origin rpy="-1.57079632679 0 1.57079632679" xyz="0 0 0.07"/>
      <geometry>
         <mesh filename="package://edrone_gazebo/urdf/stl/frame.stl" scale="0.001 0.001 0.001"/>
      </geometry>
      <material name="Black"/>
    </visual>
    <collision>
      <origin rpy="0 0 0" xyz="0 0 0.07"/>
      <geometry>
        <!--<mesh filename="package://indoor-mapping-2019/urdf/stl/Combine_Lower_Body.stl" scale="0.001 0.001 0.001"/> -->
        <cylinder length="0.004" radius="0.15"/>
      </geometry>
      <material name="White"/>
    </collision>
  </link>

  <gazebo reference="frame_link">
    <material>Gazebo/Black</material>
    <turnGravityOff>false</turnGravityOff>
  </gazebo>
  <!-- End base link -->

  <!-- Middle link  -->
  <link name="middle_link">
    <inertial>
        <mass value="0.2"/>
        <origin rpy="0 0 0" xyz="0 0 0"/>
        <inertia ixx="0.0000282916666667" ixy="0" ixz="0" iyy="0.0000282916666667" iyz="0" izz="0.00005625"/>
    </inertial>
    <visual>
      <origin rpy="-1.57079632679 0 1.57079632679" xyz="0 0 0"/>
      <geometry>
         <mesh filename="package://edrone_gazebo/urdf/stl/frame.stl" scale="0.001 0.001 0.001"/>
      </geometry>
      <material name="White"/>
    </visual>
    <collision>
      <origin rpy="-1.57079632679 0 1.57079632679" xyz="0 0 0"/>
      <geometry>
         <mesh filename="package://edrone_gazebo/urdf/stl/frame.stl" scale="0.001 0.001 0.001"/>
      </geometry>
      <material name="White"/>
    </collision>
  </link>

  <gazebo reference="middle_link">
    <material>Gazebo/White</material>
    <turnGravityOff>false</turnGravityOff>
  </gazebo>

  <joint name="middle_joint" type="fixed">
    <parent link="frame_link"/>
    <child link="middle_link"/>
    <origin rpy="0 0 0" xyz="0 0.0 .07"/>
  </joint>

  <gazebo reference="middle_link">
    <turnGravityOff>false</turnGravityOff>
    <material>Gazebo/White</material>
  </gazebo>
  <!-- End middle link -->

  <!-- Top link -->
  <link name="top_link">
    <inertial>
      <mass value="0.3"/>
      <origin rpy="0 0 0" xyz="0 0 0"/>
      <!--The 3x3 rotational inertia matrix. -->
      <inertia ixx="0.0000282916666667" ixy="0" ixz="0" iyy="0.0000282916666667" iyz="0" izz="0.00005625"/>
    </inertial>
    <visual>
      <origin rpy="-1.57079632679 0 1.57079632679" xyz="0 0 0"/>
      <geometry>
         <mesh filename="package://edrone_gazebo/urdf/stl/frame.stl" scale="0.001 0.001 0.001"/>
      </geometry>
      <material name="White"/>
    </visual>
    <collision>
      <origin rpy="-1.57079632679 0 1.57079632679" xyz="0 0 0"/>
      <geometry>
         <mesh filename="package://edrone_gazebo/urdf/stl/frame.stl" scale="0.001 0.001 0.001"/>
      </geometry>
      <material name="White"/>
    </collision>
  </link>

  <gazebo reference="top_link">
    <material>Gazebo/White</material>
    <turnGravityOff>false</turnGravityOff>
  </gazebo>

  <joint name="top_joint" type="fixed">
    <parent link="middle_link"/>
    <child link="top_link"/>
    <origin rpy="0 0 0" xyz="0 0.0 .035"/>
  </joint>

  <gazebo reference="top_link">
    <turnGravityOff>false</turnGravityOff>
    <material>Gazebo/White</material>
  </gazebo>
  <!-- End top link -->

  <!-- Right wheel -->
  <link name="right_wheel">
    <visual>
      <origin rpy="1.57079632679 0  0 " xyz="0 0 0"/>
      <geometry>
        <cylinder length="0.04" radius="0.035"/>
      </geometry>
      <material name="Green"/>
    </visual>
    <collision>
      <origin rpy="1.57079632679 0 0 " xyz="0 0 0"/>
      <geometry>
        <cylinder length="0.04" radius="0.035"/>
      </geometry>
    </collision>
    <inertial>
      <mass value="0.5"/>
      <origin xyz="0 0 0"/>
      <inertia ixx="0.0001" ixy="0" ixz="0" iyy="0.0001" iyz="0" izz="0.0001"/>
    </inertial>
  </link>

  <gazebo reference="right_wheel">
    <mu1 value="1.0"/>
    <mu2 value="1.0"/>
    <kp value="100000.0"/>
    <kd value="1.0"/>
    <fdir1 value="1 0 0"/>
    <material>Gazebo/Green</material>
    <turnGravityOff>false</turnGravityOff>
  </gazebo>

  <joint name="right_wheel_joint" type="continuous">
    <parent link="frame_link"/>
    <child link="right_wheel"/>
      <origin rpy="0 0 0" xyz="0.0 0.138 0.035"/>
    <axis rpy="0 0 0" xyz="0 1 0"/>
    <limit effort="100" velocity="100"/>
    <joint_properties damping="0.0" friction="0.0"/>
  </joint>
  <!-- End right wheel-->

  <!-- Left wheel-->
  <link name="left_wheel">
    <visual>
      <origin rpy="1.57079632679 0  0 " xyz="0 0 0"/>
      <geometry>
        <cylinder length="0.04" radius="0.035"/>
      </geometry>
      <material name="Green"/>
    </visual>
    <collision>
      <origin rpy="1.57079632679 0 0 " xyz="0 0 0"/>
      <geometry>
        <cylinder length="0.04" radius="0.035"/>
      </geometry>
    </collision>
    <inertial>
      <mass value="0.5"/>
      <origin xyz="0 0 0"/>
      <inertia ixx="0.0001" ixy="0" ixz="0" iyy="0.0001" iyz="0" izz="0.0001"/>
    </inertial>
  </link>

  <gazebo reference="left_wheel">
    <mu1 value="1.0"/>
    <mu2 value="1.0"/>
    <kp value="100000.0"/>
    <kd value="1.0"/>
    <fdir1 value="1 0 0"/>
    <material>Gazebo/Green</material>
    <turnGravityOff>false</turnGravityOff>
  </gazebo>

  <joint name="left_wheel_joint" type="continuous">
    <parent link="frame_link"/>
    <child link="left_wheel"/>
    <origin rpy="0 0 0" xyz="0 -0.138 0.035"/>
    <axis rpy="0  0" xyz="0 1 0"/>
    <limit effort="100" velocity="100"/>
    <joint_properties damping="0.0" friction="0.0"/>
  </joint>

  <!-- Transmission is important to link the joints and the controller -->
  <transmission name="right_wheel_joint_trans">
    <type>transmission_interface/SimpleTransmission</type>
    <joint name="right_wheel_joint"/>
    <actuator name="right_wheel_joint_motor">
      <hardwareInterface>EffortJointInterface</hardwareInterface>
      <mechanicalReduction>1</mechanicalReduction>
    </actuator>
  </transmission>

  <transmission name="left_wheel_joint_trans">
    <type>transmission_interface/SimpleTransmission</type>
    <joint name="left_wheel_joint"/>
    <actuator name="left_wheel_joint_motor">
      <hardwareInterface>EffortJointInterface</hardwareInterface>
      <mechanicalReduction>1</mechanicalReduction>
    </actuator>
  </transmission>


  <!-- Front Caster -->
  <link name="caster_front_link">
    <visual>
      <origin rpy="1.57079632679 0 0" xyz="0 0 0"/>
      <geometry>
        <sphere radius="0.01214"/>
      </geometry>
      <material name="White"/>
    </visual>
    <collision>
      <geometry>
        <sphere radius="0.007"/>
      </geometry>
      <origin rpy="1.57079632679 0 0" xyz="0 0 0"/>
    </collision>
    <inertial>
      <mass value="0.01"/>
      <origin xyz="0 0 0"/>
      <inertia ixx="0.0000001" ixy="0.0" ixz="0.0" iyy="0.0000001" iyz="0.0" izz="0.0000001"/>
    </inertial>
  </link>
  <joint name="caster_front_joint" type="continuous">
    <parent link="caster_link"/>
    <child link="caster_front_link"/>
    <origin rpy="0 0 0" xyz="0.05 0 -0.0275"/>
    <axis rpy="0 0 0" xyz="0 1 0"/>
  </joint>
  <gazebo reference="caster_front_link">
  <!--
    <mu1 value="1.0"/>
    <mu2 value="1.0"/>
    <kp value="100000.0"/>
    <kd value="1.0"/>
    <fdir1 value="1 1 0"/>
  -->
    <turnGravityOff>false</turnGravityOff>
    <material>Gazebo/White</material>
  </gazebo>

  <link name="caster_link">
    <visual>
      <origin rpy="0 0  0 " xyz="0.05 0 0"/>
      <geometry>
        <cylinder length="0.065" radius="0.01214"/>
      </geometry>
      <material name="Green"/>
    </visual>
    <collision>
      <origin rpy="0 0 0 " xyz="0.05 0 0"/>
      <geometry>
        <cylinder length="0.065" radius="0.005"/>
      </geometry>
    </collision>
    <inertial>
      <mass value="0.05"/>
      <origin xyz="0.05 0 0"/>
      <inertia ixx="0.00001" ixy="0" ixz="0" iyy="0.00001" iyz="0" izz="0.00001"/>
    </inertial>
  </link>

  <joint name="caster_front_joint_base" type="fixed">
    <parent link="frame_link"/>
    <child link="caster_link"/>
    <origin rpy="0 0 0" xyz="0.07 0.0 .035"/>
  </joint>

  <gazebo reference="caster_link">
    <turnGravityOff>false</turnGravityOff>
    <material>Gazebo/White</material>
  </gazebo>

  <!-- Back caster  -->
  <link name="caster_back_link">
    <visual>
      <origin rpy="1.57079632679 0 0" xyz="0 0 0"/>
      <geometry>
        <sphere radius="0.01214"/>
      </geometry>
      <material name="White"/>
    </visual>
    <collision>
      <geometry>
        <sphere radius="0.007"/>
      </geometry>
      <origin rpy="1.57079632679 0 0" xyz="0 0 0"/>
    </collision>
    <inertial>
      <mass value="0.01"/>
      <origin xyz="0 0 0"/>
      <inertia ixx="0.0000001" ixy="0.0" ixz="0.0" iyy="0.0000001" iyz="0.0" izz="0.0000001"/>
    </inertial>
  </link>
  <joint name="caster_back_joint" type="continuous">
    <parent link="caster_b_link"/>
    <child link="caster_back_link"/>
    <origin rpy="0 0 0" xyz="0.05 0 -0.0275"/>
    <axis rpy="0 0 0" xyz="0 1 0"/>
  </joint>

  <gazebo reference="caster_front_link">
  <!--
    <mu1 value="1.0"/>
    <mu2 value="1.0"/>
    <kp value="100000.0"/>
    <kd value="1.0"/>
    <fdir1 value="1 1 0"/>
  -->
    <turnGravityOff>false</turnGravityOff>
    <material>Gazebo/White</material>
  </gazebo>

  <link name="caster_b_link">
    <visual>
      <origin rpy="0 0  0 " xyz="0.05 0 0"/>
      <geometry>
        <cylinder length="0.065" radius="0.01214"/>
      </geometry>
      <material name="Green"/>
    </visual>
    <collision>
      <origin rpy="0 0 0 " xyz="0.05 0 0"/>
      <geometry>
        <cylinder length="0.065" radius="0.005"/>
      </geometry>
    </collision>
    <inertial>
      <mass value="0.05"/>
      <origin xyz="0.05 0 0"/>
      <inertia ixx="0.00001" ixy="0" ixz="0" iyy="0.00001" iyz="0" izz="0.00001"/>
    </inertial>
  </link>

  <joint name="caster_back_joint_base" type="fixed">
    <parent link="frame_link"/>
    <child link="caster_b_link"/>
    <origin rpy="0 0 0" xyz="-0.16 0.0 .035"/>
  </joint>

  <gazebo reference="caster_link">
    <turnGravityOff>false</turnGravityOff>
    <material>Gazebo/White</material>
  </gazebo>


</robot>
