<?xml version="1.0" ?>

<robot name="edrone_model" xmlns:xacro="http://www.ros.org/wiki/xacro">

  <!-- Defining the colors used in this robot -->
  <material name="Black">
    <color rgba="0.0 0.0 0.0 1.0"/>
  </material>
  <material name="Red">
    <color rgba="0.8 0.0 0.0 1.0"/>
  </material>
  <material name="Green">
    <color rgba="0.0 0.8 0.0 1.0"/>
  </material>
  <material name="White">
    <color rgba="1.0 1.0 1.0 1.0"/>
  </material>
  <material name="Blue">
    <color rgba="0.0 0.0 0.8 1.0"/>
  </material>
  --&gt;

  <!-- BASE-LINK -->
  <!--Actual body/chassis of the robot-->
  <link name="frame_link">
    <visual>
      <origin rpy="-1.57079632679 0 1.57079632679" xyz="0 0 0.07"/>
      <geometry>
         <mesh filename="package://edrone_gazebo/urdf/stl/frame.stl" scale="0.001 0.001 0.001"/>
      </geometry>
      <material name="Black"/>
    </visual>
    <collision>
      <origin rpy="0 0 0" xyz="0 0 0.07"/>
      <geometry>
        <!--<mesh filename="package://indoor-mapping-2019/urdf/stl/Combine_Lower_Body.stl" scale="0.001 0.001 0.001"/> -->
        <cylinder length="0.004" radius="0.15"/>
      </geometry>
      <material name="White"/>
    </collision>
  </link>

  <gazebo reference="frame_link">
    <material>Gazebo/Black</material>
    <turnGravityOff>false</turnGravityOff>
  </gazebo>
  <!-- End base link -->

  <!-- Middle link  -->
  <link name="middle_link">
    <inertial>
        <mass value="0.2"/>
        <origin rpy="0 0 0" xyz="0 0 0"/>
        <inertia ixx="0.0000282916666667" ixy="0" ixz="0" iyy="0.0000282916666667" iyz="0" izz="0.00005625"/>
    </inertial>
    <visual>
      <origin rpy="-1.57079632679 0 1.57079632679" xyz="0 0 0"/>
      <geometry>
         <mesh filename="package://edrone_gazebo/urdf/stl/frame.stl" scale="0.001 0.001 0.001"/>
      </geometry>
      <material name="White"/>
    </visual>
    <collision>
      <origin rpy="-1.57079632679 0 1.57079632679" xyz="0 0 0"/>
      <geometry>
         <mesh filename="package://edrone_gazebo/urdf/stl/frame.stl" scale="0.001 0.001 0.001"/>
      </geometry>
      <material name="White"/>
    </collision>
  </link>

  <gazebo reference="middle_link">
    <material>Gazebo/White</material>
    <turnGravityOff>false</turnGravityOff>
  </gazebo>

  <joint name="middle_joint" type="fixed">
    <parent link="frame_link"/>
    <child link="middle_link"/>
    <origin rpy="0 0 0" xyz="0 0.0 .07"/>
  </joint>

  <gazebo reference="middle_link">
    <turnGravityOff>false</turnGravityOff>
    <material>Gazebo/White</material>
  </gazebo>
  <!-- End middle link -->

  <!-- Top link -->
  <link name="top_link">
    <inertial>
      <mass value="0.3"/>
      <origin rpy="0 0 0" xyz="0 0 0"/>
      <!--The 3x3 rotational inertia matrix. -->
      <inertia ixx="0.0000282916666667" ixy="0" ixz="0" iyy="0.0000282916666667" iyz="0" izz="0.00005625"/>
    </inertial>
    <visual>
      <origin rpy="-1.57079632679 0 1.57079632679" xyz="0 0 0"/>
      <geometry>
         <mesh filename="package://edrone_gazebo/urdf/stl/frame.stl" scale="0.001 0.001 0.001"/>
      </geometry>
      <material name="White"/>
    </visual>
    <collision>
      <origin rpy="-1.57079632679 0 1.57079632679" xyz="0 0 0"/>
      <geometry>
         <mesh filename="package://edrone_gazebo/urdf/stl/frame.stl" scale="0.001 0.001 0.001"/>
      </geometry>
      <material name="White"/>
    </collision>
  </link>

  <gazebo reference="top_link">
    <material>Gazebo/White</material>
    <turnGravityOff>false</turnGravityOff>
  </gazebo>

  <joint name="top_joint" type="fixed">
    <parent link="middle_link"/>
    <child link="top_link"/>
    <origin rpy="0 0 0" xyz="0 0.0 .035"/>
  </joint>

  <gazebo reference="top_link">
    <turnGravityOff>false</turnGravityOff>
    <material>Gazebo/White</material>
  </gazebo>
  <!-- End top link -->

  <!-- Right wheel -->
  <link name="right_wheel">
    <visual>
      <origin rpy="1.57079632679 0  0 " xyz="0 0 0"/>
      <geometry>
        <cylinder length="0.04" radius="0.035"/>
      </geometry>
      <material name="Green"/>
    </visual>
    <collision>
      <origin rpy="1.57079632679 0 0 " xyz="0 0 0"/>
      <geometry>
        <cylinder length="0.04" radius="0.035"/>
      </geometry>
    </collision>
    <inertial>
      <mass value="0.5"/>
      <origin xyz="0 0 0"/>
      <inertia ixx="0.0001" ixy="0" ixz="0" iyy="0.0001" iyz="0" izz="0.0001"/>
    </inertial>
  </link>

  <gazebo reference="right_wheel">
    <mu1 value="1.0"/>
    <mu2 value="1.0"/>
    <kp value="100000.0"/>
    <kd value="1.0"/>
    <fdir1 value="1 0 0"/>
    <material>Gazebo/Green</material>
    <turnGravityOff>false</turnGravityOff>
  </gazebo>

  <joint name="right_wheel_joint" type="continuous">
    <parent link="frame_link"/>
    <child link="right_wheel"/>
      <origin rpy="0 0 0" xyz="0.0 0.138 0.035"/>
    <axis rpy="0 0 0" xyz="0 1 0"/>
    <limit effort="100" velocity="100"/>
    <joint_properties damping="0.0" friction="0.0"/>
  </joint>
  <!-- End right wheel-->

  <!-- Left wheel-->
  <link name="left_wheel">
    <visual>
      <origin rpy="1.57079632679 0  0 " xyz="0 0 0"/>
      <geometry>
        <cylinder length="0.04" radius="0.035"/>
      </geometry>
      <material name="Green"/>
    </visual>
    <collision>
      <origin rpy="1.57079632679 0 0 " xyz="0 0 0"/>
      <geometry>
        <cylinder length="0.04" radius="0.035"/>
      </geometry>
    </collision>
    <inertial>
      <mass value="0.5"/>
      <origin xyz="0 0 0"/>
      <inertia ixx="0.0001" ixy="0" ixz="0" iyy="0.0001" iyz="0" izz="0.0001"/>
    </inertial>
  </link>

  <gazebo reference="left_wheel">
    <mu1 value="1.0"/>
    <mu2 value="1.0"/>
    <kp value="100000.0"/>
    <kd value="1.0"/>
    <fdir1 value="1 0 0"/>
    <material>Gazebo/Green</material>
    <turnGravityOff>false</turnGravityOff>
  </gazebo>

  <joint name="left_wheel_joint" type="continuous">
    <parent link="frame_link"/>
    <child link="left_wheel"/>
    <origin rpy="0 0 0" xyz="0 -0.138 0.035"/>
    <axis rpy="0  0" xyz="0 1 0"/>
    <limit effort="100" velocity="100"/>
    <joint_properties damping="0.0" friction="0.0"/>
  </joint>

  <!-- Transmission is important to link the joints and the controller -->
  <transmission name="right_wheel_joint_trans">
    <type>transmission_interface/SimpleTransmission</type>
    <joint name="right_wheel_joint"/>
    <actuator name="right_wheel_joint_motor">
      <hardwareInterface>EffortJointInterface</hardwareInterface>
      <mechanicalReduction>1</mechanicalReduction>
    </actuator>
  </transmission>

  <transmission name="left_wheel_joint_trans">
    <type>transmission_interface/SimpleTransmission</type>
    <joint name="left_wheel_joint"/>
    <actuator name="left_wheel_joint_motor">
      <hardwareInterface>EffortJointInterface</hardwareInterface>
      <mechanicalReduction>1</mechanicalReduction>
    </actuator>
  </transmission>


  <!-- Front Caster -->
  <link name="caster_front_link">
    <visual>
      <origin rpy="1.57079632679 0 0" xyz="0 0 0"/>
      <geometry>
        <sphere radius="0.01214"/>
      </geometry>
      <material name="White"/>
    </visual>
    <collision>
      <geometry>
        <sphere radius="0.007"/>
      </geometry>
      <origin rpy="1.57079632679 0 0" xyz="0 0 0"/>
    </collision>
    <inertial>
      <mass value="0.01"/>
      <origin xyz="0 0 0"/>
      <inertia ixx="0.0000001" ixy="0.0" ixz="0.0" iyy="0.0000001" iyz="0.0" izz="0.0000001"/>
    </inertial>
  </link>
  <joint name="caster_front_joint" type="continuous">
    <parent link="caster_link"/>
    <child link="caster_front_link"/>
    <origin rpy="0 0 0" xyz="0.05 0 -0.0275"/>
    <axis rpy="0 0 0" xyz="0 1 0"/>
  </joint>
  <gazebo reference="caster_front_link">
  <!--
    <mu1 value="1.0"/>
    <mu2 value="1.0"/>
    <kp value="100000.0"/>
    <kd value="1.0"/>
    <fdir1 value="1 1 0"/>
  -->
    <turnGravityOff>false</turnGravityOff>
    <material>Gazebo/White</material>
  </gazebo>

  <link name="caster_link">
    <visual>
      <origin rpy="0 0  0 " xyz="0.05 0 0"/>
      <geometry>
        <cylinder length="0.065" radius="0.01214"/>
      </geometry>
      <material name="Green"/>
    </visual>
    <collision>
      <origin rpy="0 0 0 " xyz="0.05 0 0"/>
      <geometry>
        <cylinder length="0.065" radius="0.005"/>
      </geometry>
    </collision>
    <inertial>
      <mass value="0.05"/>
      <origin xyz="0.05 0 0"/>
      <inertia ixx="0.00001" ixy="0" ixz="0" iyy="0.00001" iyz="0" izz="0.00001"/>
    </inertial>
  </link>

  <joint name="caster_front_joint_base" type="fixed">
    <parent link="frame_link"/>
    <child link="caster_link"/>
    <origin rpy="0 0 0" xyz="0.07 0.0 .035"/>
  </joint>

  <gazebo reference="caster_link">
    <turnGravityOff>false</turnGravityOff>
    <material>Gazebo/White</material>
  </gazebo>

  <!-- Back caster  -->
  <link name="caster_back_link">
    <visual>
      <origin rpy="1.57079632679 0 0" xyz="0 0 0"/>
      <geometry>
        <sphere radius="0.01214"/>
      </geometry>
      <material name="White"/>
    </visual>
    <collision>
      <geometry>
        <sphere radius="0.007"/>
      </geometry>
      <origin rpy="1.57079632679 0 0" xyz="0 0 0"/>
    </collision>
    <inertial>
      <mass value="0.01"/>
      <origin xyz="0 0 0"/>
      <inertia ixx="0.0000001" ixy="0.0" ixz="0.0" iyy="0.0000001" iyz="0.0" izz="0.0000001"/>
    </inertial>
  </link>
  <joint name="caster_back_joint" type="continuous">
    <parent link="caster_b_link"/>
    <child link="caster_back_link"/>
    <origin rpy="0 0 0" xyz="0.05 0 -0.0275"/>
    <axis rpy="0 0 0" xyz="0 1 0"/>
  </joint>

  <gazebo reference="caster_front_link">
  <!--
    <mu1 value="1.0"/>
    <mu2 value="1.0"/>
    <kp value="100000.0"/>
    <kd value="1.0"/>
    <fdir1 value="1 1 0"/>
  -->
    <turnGravityOff>false</turnGravityOff>
    <material>Gazebo/White</material>
  </gazebo>

  <link name="caster_b_link">
    <visual>
      <origin rpy="0 0  0 " xyz="0.05 0 0"/>
      <geometry>
        <cylinder length="0.065" radius="0.01214"/>
      </geometry>
      <material name="Green"/>
    </visual>
    <collision>
      <origin rpy="0 0 0 " xyz="0.05 0 0"/>
      <geometry>
        <cylinder length="0.065" radius="0.005"/>
      </geometry>
    </collision>
    <inertial>
      <mass value="0.05"/>
      <origin xyz="0.05 0 0"/>
      <inertia ixx="0.00001" ixy="0" ixz="0" iyy="0.00001" iyz="0" izz="0.00001"/>
    </inertial>
  </link>

  <joint name="caster_back_joint_base" type="fixed">
    <parent link="frame_link"/>
    <child link="caster_b_link"/>
    <origin rpy="0 0 0" xyz="-0.16 0.0 .035"/>
  </joint>

  <gazebo reference="caster_link">
    <turnGravityOff>false</turnGravityOff>
    <material>Gazebo/White</material>
  </gazebo>

  <!-- Kinect sensor -->
  <link name="kinect_link" >
    <inertial>
      <mass value="0.1"/>
      <origin rpy="0 0 0" xyz="0 0 0"/>
      <inertia ixx="0.0000282916666667" ixy="0" ixz="0" iyy="0.0000282916666667" iyz="0" izz="0.00005625"/>
    </inertial>
    <visual>
      <origin rpy="0 0 0" xyz="0 0 0"/>
      <geometry>
            <mesh filename="package://indoor-mapping-2019/urdf/meshes/kinect.stl" scale="0.001 0.001 0.001"/>
      </geometry>
      <material name="Black"/>
    </visual>
    <collision>
      <origin rpy="0 0 0" xyz="0 0 0"/>
      <geometry>
        <cylinder length="0.065" radius="0.005"/>
      </geometry>
      <material name="Black"/>
    </collision>
  </link>

  <joint name="kinect_joint" type="fixed">
    <parent link="middle_link"/>
    <child link="kinect_link"/>
    <origin rpy="0 0 0" xyz="0.075 0.0 0.155"/>
  </joint>

  <gazebo reference="kinect_link">
    <turnGravityOff>false</turnGravityOff>
    <material>Gazebo/Black</material>
  </gazebo>
  <!-- End kinect sensor -->

  <!-- Dummy link to hold camera -->
  <!-- Ensures that transformations can be applied to pointcloud data without affecting the kinect link-->
  <link name="camera_link" >
  </link>

  <joint name="camera_joint" type="fixed">
    <parent link="kinect_link"/>
    <child link="camera_link"/>
      <origin rpy="0 0 0" xyz="0 0 0"/>
  </joint>
  <!-- End dummy link -->

  <!-- Gazebo kinect camera plugin -->
  <gazebo reference="camera_link">
    <sensor name='camera' type='depth'>
      <always_on>1</always_on>
      <update_rate>20</update_rate>
      <camera name='__default__'>
        <horizontal_fov>1.0472</horizontal_fov>
        <image>
          <format>B8G8R8</format>
          <width>640</width>
          <height>480</height>
        </image>
        <clip>
          <near>0.05</near>
          <far>8</far>
        </clip>
      </camera>
      <plugin name='kinect_camera_controller' filename='libgazebo_ros_openni_kinect.so'>
        <cameraName>camera</cameraName>
        <alwaysOn>true</alwaysOn>
        <updateRate>10</updateRate>
        <imageTopicName>rgb/image_raw</imageTopicName>
        <depthImageTopicName>depth/image_raw</depthImageTopicName>
        <pointCloudTopicName>depth/points</pointCloudTopicName>
        <cameraInfoTopicName>rgb/camera_info</cameraInfoTopicName>
        <depthImageCameraInfoTopicName>depth/camera_info</depthImageCameraInfoTopicName>
        <frameName>camera_link</frameName>
        <baseline>0.1</baseline>
        <distortion_k1>0.0</distortion_k1>
        <distortion_k2>0.0</distortion_k2>
        <distortion_k3>0.0</distortion_k3>
        <distortion_t1>0.0</distortion_t1>
        <distortion_t2>0.0</distortion_t2>
        <pointCloudCutoff>0.4</pointCloudCutoff>
        <robotNamespace>/</robotNamespace>
      </plugin>
      <pose> -0.087 -0.0015 0.2972 1.58 0 0</pose>
    </sensor>
  </gazebo>
  <!-- End kinect camera plugin -->

  <!-- Gazebo differential drive robot plugin -->
  <gazebo>
    <plugin filename="libgazebo_ros_diff_drive.so" name="differential_drive_controller_front">
      <legacyMode>True</legacyMode>
      <rosDebugLevel>False</rosDebugLevel>
      <publishWheelTF>True</publishWheelTF>
      <publishTf>true</publishTf>
      <publishWheelJointState>true</publishWheelJointState>
      <alwaysOn>true</alwaysOn>
      <updateRate>10.0</updateRate>
      <leftJoint>left_wheel_joint</leftJoint>
      <rightJoint>right_wheel_joint</rightJoint>
      <wheelSeparation>0.3</wheelSeparation>
      <wheelDiameter>0.065</wheelDiameter>
      <broadcastTF>true</broadcastTF>
      <wheelTorque>30</wheelTorque>
      <wheelAcceleration>1.8</wheelAcceleration>
      <commandTopic>cmd_vel</commandTopic>
      <publishOdomTF>true</publishOdomTF>
      <odometrySource>world</odometrySource>
      <odometryFrame>odom</odometryFrame>
      <odometryTopic>odom</odometryTopic>
      <robotBaseFrame>frame_link</robotBaseFrame>
    </plugin>
  </gazebo>
  <!-- End differential drive plugin -->

</robot>
